Workbook

Sheet Waterfall for 3 Criteria
A1: Notes: 1. Based on Oct 2025 - Sept 2026, ePAs only, Original Review, Commercial and Specialty LOBs 2. Excludes FEP, Data Entry and Medicaid LoBs, Non ePAs, Appeals 3. Focus only on 3 PACs - PAC131011, PAC20883, PAC33295 for PA Caddie Pilot launch
O5: Q: how much is this from Loop1 on ops cost
F11: Oct 2025 - Sept 2026 | G11: Wegovy (PAC131011) | N11: IBRs (PAC20883) | U11: Formulary Exeptions (PAC33295)
G12: Case Volume | H12: Approved Cases | I12: % Approval Rate | J12: Cost | K12: Cost per PA | L12: AHT | M12: Avg Tasks per PA (excludes Touches) | N12: Case Volume | O12: Approved Cases | P12: % Approval Rate | Q12: Cost | R12: Cost per PA | S12: AHT | T12: Avg Tasks per PA (excludes Touches) | U12: Case Volume | V12: Approved Cases | W12: % Approval Rate | X12: Cost | Y12: Cost per PA | Z12: AHT | AA12: Avg Tasks per PA (excludes Touches)
F13: All PA Cases | G13: ='WF 1'!E30 -> 913153 | H13: ='WF 1'!F30 -> 650054 | I13: =H13/G13 -> 0.71187851 | J13: ='WF 1'!H30 -> 5448988.2 | K13: =J13/G13 -> 5.9672237 | L13: ='WF 1'!L30 -> 221.837 | M13: 1.06 | N13: 389000 | O13: 4 | P13: =O13/N13 -> 1.0282776e-05 | Q13: 1000000 | R13: =IFERROR(Q13/N13, 0) -> 2.5706941 | S13: 147 | T13: 1.84 | U13: 75000 | V13: 25000 | W13: =IFERROR(V13/U13,0) -> 0.33333333 | X13: 1140000 | Y13: =IFERROR(X13/U13,0) -> 15.2 | Z13: 492 | AA13: 1.82
F14: ePAs Auto Approved | G14: ='WF 1'!E31 -> 239853 | H14: ='WF 1'!F31 -> 239853 | I14: =H14/G14 -> 1 | J14: ='WF 1'!H31 -> 48701 | K14: =J14/G14 -> 0.2030452 | L14: ='WF 1'!L31 -> 10.840098 | M14: 0.1 | N14: 0 | O14: 0 | P14: - | Q14: 0 | R14: =IFERROR(Q14/N14, 0) -> 0 | S14: - | T14: - | U14: - | V14: - | W14: - | X14: - | Y14: - | Z14: - | AA14: -
F15: ePAs Human Reviewed | G15: ='WF 1'!E32 -> 673300 | H15: ='WF 1'!F32 -> 410201 | I15: =H15/G15 -> 0.60923957 | J15: ='WF 1'!H32 -> 5400287.2 | K15: =J15/G15 -> 8.0206256 | L15: ='WF 1'!L32 -> 297.00148 | M15: 1.41 | N15: 389000 | O15: 4 | P15: =O15/N15 -> 1.0282776e-05 | Q15: 1000000 | R15: =IFERROR(Q15/N15, 0) -> 2.5706941 | S15: 147 | T15: 1.84 | U15: 75000 | V15: 25000 | W15: =IFERROR(V15/U15,0) -> 0.33333333 | X15: 1140000 | Y15: =IFERROR(X15/U15,0) -> 15.2 | Z15: 492 | AA15: 1.82
F16: ePA Scored Approval | G16: ='WF 1'!E33 -> 358815 | H16: ='WF 1'!F33 -> 306354 | I16: =H16/G16 -> 0.85379374 | J16: ='WF 1'!H33 -> 3151440 | K16: =J16/G16 -> 8.7829104 | L16: ='WF 1'!L33 -> 382.24852 | M16: 1.76 | N16: 286000 | O16: 4 | P16: =O16/N16 -> 1.3986014e-05 | Q16: 748000 | R16: =IFERROR(Q16/N16, 0) -> 2.6153846 | S16: 160 | T16: 2.06 | U16: 50000 | V16: 21000 | W16: =IFERROR(V16/U16,0) -> 0.42 | X16: 847000 | Y16: =IFERROR(X16/U16,0) -> 16.94 | Z16: 583 | AA16: 2.47
F17: ePA Scored Denial | G17: ='WF 1'!E35 -> 181455 | H17: ='WF 1'!F35 -> 84875 | I17: =H17/G17 -> 0.46774682 | J17: ='WF 1'!H35 -> 1744584 | K17: =J17/G17 -> 9.6144168 | L17: ='WF 1'!L35 -> 248.43444 | M17: 1.23 | N17: 9000 | O17: 0 | P17: =O17/N17 -> 0 | Q17: 119000 | R17: =IFERROR(Q17/N17, 0) -> 13.222222 | S17: 331 | T17: 1.4 | U17: 23400 | V17: 3000 | W17: =IFERROR(V17/U17,0) -> 0.12820513 | X17: 222000 | Y17: =IFERROR(X17/U17,0) -> 9.4871795 | Z17: 263 | AA17: 1.27
F18: ePA Unscored | G18: ='WF 1'!E38 -> 114090 | H18: ='WF 1'!F38 -> 110 | I18: =H18/G18 -> 0.00096415111 | J18: ='WF 1'!H37 -> 504263.21 | K18: =J18/G18 -> 4.4198721 | L18: ='WF 1'!L37 -> 133.31519 | M18: 0.72 | N18: 94000 | O18: 0 | P18: =O18/N18 -> 0 | Q18: 136000 | R18: =IFERROR(Q18/N18, 0) -> 1.4468085 | S18: 90 | T18: 1.21 | U18: 2000 | V18: 305 | W18: =IFERROR(V18/U18,0) -> 0.1525 | X18: 48000 | Y18: =IFERROR(X18/U18,0) -> 24 | Z18: 794 | AA18: 0.63

Sheet Consolidated Flow
A1: Consolidated flow - which steps are shared and which are PAC-specific - Built from Process 1 (Wegovy PAC131011, 23 steps), Process 2 (717-A, ACF PAC 33295, 13 steps) and the IBR Steps tab (PAC20883, 13 steps) - 32 steps in the order you would work a case. 'Description' says exactly what is done and what each PAC does differently - 'Data / fields' lists what the step reads (field names are the ones we have seen in CAS / EPA tables) - Build Overall: get the case, verify the drug, claim and reject, PA history, Auto Note, dates, close and finish - Same step, flipped rule: the reject check and the criteria-form check. Wegovy and 717-A need a PA reject and a form; IBR needs a non-PA reject and NO form - PAC-specific: Wegovy = answers, chart notes, weight / BMI math, override; 717-A = formulary alternatives, Q2 review, partial macro, post-approval claim; IBR = exceptions and plan checks, 60-day IBR count, denial reason, California routing
A12: # | B12: Phase | C12: Step (plain) | D12: Description (what exactly happens) | E12: Wegovy (PAC131011) | F12: 717-A (ACF PAC 33295) | G12: IBR (PAC20883) | H12: Same across all 3? | I12: Source steps (P1 / P2 / P3) | J12: Data / fields we think it uses | K12: Build note | L12: Loop 1 or 2? | M12: Automation Potential
A13: 1 | B13: Get the case | C13: Get the PA | D13: 1. Pick up the next case to work 2. All PACs: Smart Routing 'Get Next' opens the PA in CAS with a PASTA message (the fallout reason and the actions to do) 3. A tech can also pull a PA by hand from the queue; then there is no PASTA message and the tech does every check 4. If Smart Routing is down, use the Downtime WI 5. IBR: the request can also arrive as a phone call, fax, ePA Loop 1, ePA Loop 2 or Unassigned | E13: Yes - Smart Routing Get Next or manual pull | F13: Yes | G13: Yes - queue, phone, fax or ePA loop | H13: Yes | I13: P1 1 / P2 1 / IBR 7 | J13: PA number (CAS_PA_NUMBER); channel the request came in on; PASTA message text | K13: Shared. In V1 the case comes from the ePA feed. | M13: Yes - Smart Routing integration
A14: 2 | B14: Get the case | C14: Read the fallout message and the Messages / Guidelines / Red Message tabs | D14: 1. Read the case briefing, then do what it says 2. All PACs: read the PASTA message, then the Messages, Guidelines, Work Instructions and Red Message tabs for this member's client 3. Wegovy: some clients are worked by a dedicated team (e.g. Wellmark, FLBL, HealthFirst). For those, IM the team the PA number and stop - do not work the case. 4. IBR: the Red Message tab also shows whether the client sends IBRs and any client-specific rules (for example, no 60-day limit). | E14: Yes - PASTA message plus tabs; dedicated-team client = IM the team and stop | F14: Not listed in Process 2 | G14: Yes - Red Message tab for client rules and IBR opt-out | H14: Mostly | I14: P1 2 / - / IBR 2 | J14: Client / PAG (CAS_PAGCODE); PASTA text; Red Message and Guidelines text for the client | K14: Shared 'case briefing' panel. Client flags differ per PAC. | M14: Yes - Super PASTA integration, surface relevant context only Q: is SR not client-aware? Those cases should be going to that team directly
A15: 3 | B15: Get the case | C15: Verify the drug name | D15: 1. Make sure the drug on the PA is the right CAS drug, so the right criteria and macros load 2. All PACs: re-select the drug from the drop-down even if it is pre-filled, then check strength 3. brand vs generic and form against the claim. If the only option is 'Other, please specify', move on 4. Why: the ePA vendor and CAS can name the same drug differently (vendor-to-admin mismatch) 5. IBR: only needs a drug and prescriber entered; 'Other' is allowed for both. | E15: Yes - re-select so macros load; check strength / brand / form | F15: Yes - fixes vendor-to-admin drug mismatch | G15: Light - enter drug and prescriber; 'Other' allowed | H15: Mostly | I15: P1 3 / P2 2 / IBR 7 | J15: Claim GPI (NCPDP_GPI) and NDC (NCPDP_NDC, left-pad to 11 digits); CAS drug lists (ASAP.DRUGLIST, ASAP.PAGDRUGLIST) matched at GPI 14 / 12 / 10; prescribed drug name | K15: Shared (our CAS drug-name resolver). | M15: Mixed - easy for Wegovy, hard for others. Will need to load full options from CAS
A16: 4 | B16: Get the case | C16: Make sure the rejected claim is attached | D16: 1. Make sure the rejected claim that started this PA is attached and is the right one. 2. Wegovy: check the Claims tab. If you attach one yourself, click Cancel on the next pop-up. On an ePA with no rejected claim, do NOT tick 'Rejected Claim Not Available'. 3. 717-A: not listed separately; the claim comes with the test claim 4. IBR: attach a rejected claim from the last 7 days. If there is none, or it is older than 7 days, DO tick 'Rejected Claim Not Available' (opposite of the Wegovy ePA rule). | E16: Yes - attach the right claim, do not tick 'Rejected Claim Not Available' on ePA | F16: Not listed (comes with the test claim) | G16: Yes - claim from last 7 days, else tick 'Rejected Claim Not Available' | H16: Mostly | I16: P1 4 / P2 3 / IBR 7 | J16: Claim number and sequence (ASAP.MEMBERCLAIM CLAIMNUMBER, SEQUENCENUMBER); claim date; reject code on that claim | K16: Shared claim panel; the 7-day rule is IBR only. | M16: Yes - look up recent claims, match on drug and select. Fallout if n_matches != 1
A17: 5 | B17: Is it right? | C17: Run the test / mock claim and read the reject | D17: 1. Run a test (mock) claim and read what it rejects with 2. Wegovy: run for today, +30 and +60 days (never +90). A PA-required reject (75, or 70 with a PA phone number) means continue. If the claim pays, check for overrides in the PA History step. 3. 'Refill too soon' (79): re-run at the Next Available Fill Date to see the true reject. Other codes: use the rejection WI 3. 717-A: same, and check RMT if more information is needed 4. IBR: same test claim, but a non-PA reject is what you want | E17: Yes - today, +30, +60, never +90 | F17: Yes - run initial test claim, check RMT | G17: Yes - test claim, read reject type | H17: Yes | I17: P1 5 / P2 3 / IBR 1 | J17: Reject code(s), reject message and reject phone (NCPDP_REJECTCODES, NCPDP_REJECTMSGS, NCPDP_REJECTPHONES on the ePA intake row); CAS mock claim results (ASAP.MOCK_CLAIM_RESULTS, initial mock). | K17: Shared. Mock-claim dates differ by PAC. | M17: Yes - for epa just referenced mock results of automated check
A18: 6 | B18: Is it right? | C18: Decide if the reject fits this PAC | D18: 1. Decide whether this reject fits the PAC being worked 2. Wegovy / 717-A: needs a PA reject. Our pre-check treats 70, 75 and 76 as PA-required; any other code is routed per that reject. If the claim is not a PA reject, follow the non-PA path 3. IBR: needs a non-PA benefit reject (not covered, non-formulary, copay, mail, quantity, age, out of network, step, etc.). A reject that carries a PA phone number is NOT an IBR - stop 4. Brand Strategy Formulary clients reject 606 on generics: that is an IBR. Reject 70 with a '+' in the text: check the Red Message tab for a formulary exception first | E18: Needs a PA reject (70/75/76, Commercial PA phone); paid = check overrides | F18: Needs a PA reject; no PA = non-PA path | G18: Needs a NON-PA reject; a PA phone number = stop | H18: No | I18: P1 5 / P2 3 / IBR 1 | J18: Reject code and reject phone from the previous step. | K18: Same reject, opposite pass rule. One check with a 'wanted outcome' setting per PAC. | M18: Yes - simple enough logic for most cases. workflow needs to react to this, may need to abort PA Q: does the fill date matter? Sometimes it'll reject for PA but not until later I think?
A19: 7 | B19: Is it right? | C19: Check PA history | D19: 1. Look at what has already happened on this member and drug 2. Wegovy: an active approval or an override the system loaded 3. Auto-approved by System Services: complete normally (duplicate override, void neither). 4. VTPA or plan-sponsor override in AS400: re-run the mock after it expires, complete, do not abort 5. Duplicate approval / denial / pending: apply the duplicate rules and close with ePA Abort 6. 717-A: 2 denials within 60 days = route to Appeals 7. Active appeal pending = abort. Prior appeal completed and still inside the next-level appeal window = abort and send to Appeals 8. On second or later touches also read prior reviewer notes, fax history and prescriber responses. 9. IBR: count IBRs on file for the same drug in the last 60 days (two = send to Appeals, see IBR Steps tab step 4) | E19: Yes - active approval, system override, duplicates, VTPA / plan-sponsor override | F19: Yes - 2 denials in 60 days = Appeals; pending appeal = abort | G19: Yes - count IBRs in 60 days | H19: Mostly | I19: P1 6 / P2 5 / IBR 4 | J19: PA history for the member and drug: PA type, date, outcome, appeal status, notes (ASAP.PAMAIN / ASAP.PACASE); AS400 override look-up. | K19: Shared data pull; rules per PAC. You left Wegovy blank in P1 - I say Yes. | M19: Yes - but seemingly complicated
A20: 8 | B20: Is it right? | C20: Pre-checks: exceptions, client allows it, no other path | D20: IBR only - three checks before an IBR can be issued. (a) Exception: does the member have an exception available for this reject? If yes, send to Exceptions instead (reject 70 on a call = create an ePA starter; fax / Loop 1 / Loop 2 each go to their Exceptions queue). (b) Plan allows IBR: check RMT. Suppressed = do the IBR but give the prescriber the appeals information. Not allowed = close it out by channel (Misdirected for fax, refer to plan for a call, Remove from ePA for Loop 1, Abort for Loop 2). (c) Client is not Aetna, Medicare Part D or Medicaid, and not the Drug Exclusion Formulary Exception client. Wegovy: only the dedicated-team client check (step 2). | E20: Dedicated-team client only | F20: No | G20: Yes - exception path, RMT (plan allows IBR), Seniors | H20: No | I20: P1 2 / - / IBR 2, 5, 6 | J20: Client / PAG; RMT setting 'IBR allowed / suppressed / not allowed'; Red Message exception flag; line of business. | K20: IBR-specific lookups. Strong automation candidate. | L20: this is loop 1 | M20: Maybe - not in the V1, mostly targets the loop 1 touches
A21: 9 | B21: Is it right? | C21: Confirm the criteria form | D21: Check that the criteria form (PAC) on the PA is the right one for this drug and reject. Wegovy: it should be PAC131011 'Weight Loss Wegovy PA with Limit'. To check: Change PA Type / Drug Class, click the rejected claim so reject code, phone and GPI fill in, Search, pick the PAC. Right form: Cancel, then Save. Wrong form: change it in the same case and re-enter the drug. Several forms fit: call Vetline. 717-A: compare reject code, reject phone, GPI and drug class from the mock or attached claim to the selected form. IBR: reversed - confirm NO criteria form exists. If one does, forward to the Seniors; it is a PA, not an IBR. | E21: Yes - PAC131011 Weight Loss Wegovy with Limit; change in same case if wrong | F21: Yes - verify the ACF form | G21: Flipped - confirm NO form exists (form exists = Seniors) | H21: Mostly | I21: P1 7 / P2 4 / IBR 3 | J21: PAC, PAG and question set on the PA (CAS_PACCODE, CAS_PAGCODE, CAS_QUESTIONSET_ID); question set valid for that PAG + PAC on the PA date (ASAP.QSETXREF); drug on the PAC drug list (ASAP.PAGDRUGLIST) or reject phone configured for the PAG + PAC (ASAP.PAG_PAC_PHONE) | K21: Shared QSet and drug lookup. IBR uses it as an exit. | M21: CAS Admin has configured check if there is any logic involved
A22: 10 | B22: Is it right? | C22: Check ICD-10 and that the drug name matches what we approve | D22: Two checks on the PA before reviewing answers. (1) Diagnosis: read the ICD-10 code sent with the request. It supports the diagnosis / comorbidity answers in the question set (2) Drug name: 'Requested Drug' is what the prescriber originally asked for and never changes. 'Drug Name' is what we are approving and can change. They must make sense together - for example, if the prescriber agrees in the question set to switch drugs, update Drug Name and re-run the mock claim. Wegovy only. Not listed in our 717-A or IBR sources | E22: Yes | F22: Not listed | G22: No | H22: No | I22: P1 8 / - / - | J22: ICD-10 on the request (RX_DIAGNOSIS on the ePA intake row); Requested Drug (PRESCRIBEDDRUG) and Drug Name (APPROVEDDRUG) on ASAP.PAMAIN. In live data APPROVEDDRUG is empty until after approval. | K22: Wegovy-specific; ICD-10 is on the intake row.
A23: 11 | B23: Is it right? | C23: Pull up formulary alternatives | D23: 717-A only. Look up in Guidelines the formulary alternatives required for this ACF PAC and keep that list in view while reviewing the question set and the documents. Questions Q1 and Q2 depend on it. | E23: No | F23: Yes - from Guidelines | G23: No | H23: No | I23: - / P2 6 / - | J23: Formulary alternatives list for the client / PAC (text in the Guidelines tab today). | K23: 717-A-specific. | M23: Try making a GCP table or parse from the Qset guidelines
A24: 12 | B24: Check the answers | C24: Work the question-set answers | D24: Work through the question set and check each answer against the data. 1. Wegovy: accept attestation questions as answered. Verify: age in CAS; maintenance dose and continuation in AS400 paid claims; quantity and day supply in AS400; drug / formulation. Quantity above the plan allowance, or any 'No' on a program / diet / maintenance-dose attestation = forward to RPh 2. 717-A: scored approval = verify Q2 (see Q2 step). Scored denial = find the question driving the denial: Q1 prior history and alternatives, Q2 alternatives evidence, Q3 / Q4 diagnosis or other clinical evidence; update the response if the evidence supports it, RFI if more is needed 3. Unscored questions: follow the criteria-specific workflow. 4. IBR: no clinical review | E24: Yes - age in CAS; maintenance dose / continuation, qty and days supply in AS400; accept attestations | F24: Yes - scored approval, scored denial, unscored items | G24: No clinical review | H24: No | I24: P1 9 / P2 7, 8, 9 / - | J24: Question-set answers; member age (date of birth); paid claim history (dose, quantity, days supply); quantity and days supply on the request (RX_QUANTITY, RX_DAYSSUPPLY). ASAP.MEMBERCLAIM has no quantity or days-supply columns, so those come from the MyClaims Claim Details API (claim number + sequence). | K24: PAC-specific.
A25: 13 | B25: Check the answers | C25: Read attachments / chart notes | D25: Open the attachments and read the chart notes for every question marked 'ACTION REQUIRED'. 1. Wegovy: look for baseline and current weight with dates, baseline BMI, comorbid condition, and CVD / GDMT or MASH evidence when that pathway applies. Also look for anything that contradicts the answer, and confirm the documents are for the right patient (wrong patient = email the split-fax template to CRUSrTech@CVSHealth.com) 2. Documentation missing = RFI, or forward to RPh as the WI says 3. 717-A: only when Q2 needs more reasoning or documentation | E25: Yes - weights with dates, baseline BMI, comorbidity, CVD / MASH evidence; wrong patient = split-fax email | F25: Yes - when Q2 needs more reasoning or documentation | G25: No | H25: No | I25: P1 10 / P2 9 / - | J25: Attached documents (fax / ePA attachments): weights and dates, BMI, height, comorbidity, CVD / GDMT / MASH evidence, patient name on documents. | K25: Reviewer reads; Caddie lists what to find. | M25: Suhas Take a look at this one
A26: 14 | B26: Check the answers | C26: Calculate weight loss % and BMI | D26: Wegovy only. Work out weight loss % and BMI change from the chart-note values. Weight loss % = (weight before - weight after) / weight before x 100. BMI = weight (lb) x 703 / height (in) squared, then the same % change. Do not round. Dates need at least month and year. Meets: at least 5% loss (or BMI reduction / maintained loss for continuation). Under 5%: complete denial | E26: Yes - 5% loss or BMI rule; no rounding | F26: No | G26: No | H26: No | I26: P1 11 / - / - | J26: Weight before and after (lb) with dates; height (in); baseline BMI. Entered by the reviewer from the chart notes. | K26: Wegovy calculator.
A27: 15 | B27: Check the answers | C27: Check the formulary-alternative answer (Q2) | D27: 717-A only. Check the answer to Q2 (formulary alternatives). 1. Confirm the required alternatives and whether the prescriber gave enough clinical reasoning or documentation. Free-text answers count if they sufficiently support the prescriber's intent; read clinical notes and history if more evidence is needed 2. Q2 supported = approval. More information needed = RFI. Q2 not supported = denial, based on the specific case | E27: No | F27: Yes - supported / need info / not supported | G27: No | H27: No | I27: - / P2 9 / - | J27: Q2 answer (free text); formulary alternatives list; clinical notes / history. | K27: 717-A-specific.
A28: 16 | B28: Decide | C28: Decide the outcome | D28: Choose one outcome. 1. Wegovy: meets = approve. Does not meet with complete clinical information = Tech / Nurse pend to clinician and RPh denies. Missing information = RFI. Anything the WI says to forward = RPh. Red Messages tab needing a medical director = pend to clinician 2. 717-A: approve, RFI or denial from the Q results 3. IBR: always a no-PA-required (non-clinical) denial | E28: Approve / pend to clinician / RFI / deny | F28: Approve / RFI / deny | G28: Always a no-PA-required denial | H28: No | I28: P1 12 / P2 7-9 / IBR 10 | J28: Results from the previous steps; auto-score result on the ePA submission row (AUTO_SCORE_RESULT, 'A' = scored for approval). | K28: Caddie recommends, reviewer decides.
A29: 17 | B29: Decide | C29: Pick the denial / resolution reason | D29: 1. IBR (and any denial). On the Denial tab pick the resolution reason that matches the reject type 2. There are about 25 reject types, each with its own letter wording. California plans use the 'CA IBR-' version of the same reason 3. Special cases: Plan Exclusion Non-FDA Approved / Other are HMSA only. Exceeds Claim Amount only if a senior advises. Quantity limit: not if a post-limit criteria form exists 4. Wegovy / 717-A: only when denying (clinical wording) | E29: Only when denying | F29: Only when denying | G29: Yes - from reject type (about 25 types; CA plans use 'CA IBR-' versions) | H29: No | I29: - / - / IBR 10 | J29: Reject type (from reject code / message) mapped to a resolution reason; client state (California or not). | K29: IBR is a lookup from reject type.
A30: 18 | B30: Decide | C30: Missing info: send one RFI | D30: 1. Missing information: send ONE request for information (RFI) that lists every missing item, using an RFI close option and a template under 2,000 characters 2. A second RFI on an ePA clears the ePA criteria, so one is all you get. RPh can use the combined RFI + soft denial options. 3. Wegovy and 717-A only | E30: Yes - all missing items on one RFI, under 2000 characters | F30: Yes - when more info needed | G30: No | H30: Mostly | I30: P1 S1 / P2 9 / - | J30: List of missing items; RFI template text. | K30: V1.5: Caddie drafts the RFI.
A31: 19 | B31: Document | C31: Write the PA note (Auto Note) | D31: Write the PA note. 1. Wegovy: use Auto Note after the drug name and criteria edits are final. The note has (1) outcome, (2) the ENTIRE approval message, (3) what evidence was needed, where it was found, what was found, dates and the calculation. Running Auto Note again erases the earlier Auto Note text 2. 717-A: document the review rationale; the note changes with approval, denial or RFI. IBR: notes per the CAS Notes WI (086494) | E31: Yes - outcome, full approval message, evidence and math | F31: Yes | G31: Yes - standard note, per CAS Notes WI | H31: Yes | I31: P1 13 / P2 10 / IBR 13 | J31: Outcome; approval message; evidence list with source and dates; calculation; reject. | K31: One engine, three template sets. Best first build.
A32: 20 | B32: Document | C32: Check / set the timestamps | D32: Make sure the dates are right. Wegovy: check the Completed Date auto-filled. If not, copy the Received date (RRD) into the Completed date (CD), except on an RFI. IBR: Received and Completed cannot be the same on a call. Call = 'Set to now' for both (also Verbal Notification if completed on the call; required for NY clients). Fax = the fax timestamp for both. ePA Loop 1 = the 'Edit Date' from transaction details for both. Loop 2 = see the ePA Process WI. | E32: Check auto-filled Completed Date | F32: Check auto-fill | G32: Yes - rule depends on channel (call, fax, ePA loop) | H32: Mostly | I32: P1 14 / - / IBR 8 | J32: Received date, Completed date, channel, ePA 'Edit Date'. | K32: Small shared module.
A33: 21 | B33: Close | C33: Pick close option and approval dates | D33: Pick the close option and set the approval dates. 1. Wegovy: 'Approved - ePA' (or the pend / RFI / denial option from the decision). Copy approval duration and override instructions with the QSet Copy Dialog. Choose the Resolution Reason and set approval dates from the duration. Check Start and End dates. On a denial, first check System Services did not load an override and void it in AS400. 2. 717-A: select the close option for approval, denial or RFI and fill the other required fields. 3. IBR: close option 'Initial Benefit Review'. California plans: 'Fwd to RPh CA CoC Review' (pharmacist checks continuity of care) | E33: Yes - 'Approved - ePA' or pend / RFI / denial; copy duration with QSet Copy Dialog | F33: Yes - close option activities | G33: 'Initial Benefit Review', or 'Fwd to RPh CA CoC Review' for California | H33: Mostly | I33: P1 15 / P2 11 / IBR 9 | J33: Close option; approval duration and override instructions from the question set; start and end dates; client state. | K33: Same screen. Caddie suggests; reviewer clicks in CAS in V1.
A34: 22 | B34: Close | C34: Concluded By and Member Denial note | D34: Pick who concluded the case and finish the dialog. 1. All PACs: choose your title in Concluded By (Tech, Pharmacist, Rep, LPN...) and click OK 2. IBR: also type one single space in the Member Denial note box | E34: Concluded By | F34: Concluded By | G34: Concluded By plus one space in Member Denial note | H34: Mostly | I34: P1 15 / P2 11 / IBR 11, 12 | J34: Reviewer role. | K34: Small shared module.
A35: 23 | B35: Close | C35: Finish the PA (and Smart Routing Call Notes) | D35: Click Finish to close the PA. In Smart Routing, also click Finish under Call Notes, otherwise the next Get Next gives an error | E35: Yes | F35: Yes | G35: Yes | H35: Yes | I35: P1 18 / P2 11 / IBR 13 | J35: None (a CAS / Smart Routing action). | K35: CAS action; Caddie only reminds.
A36: 24 | B36: Override | C36: See where CAS goes after OK | D36: 1. Wegovy. After OK, CAS goes one of three ways: (A) back to Member Center, (B) Override screen, (C) Mock Claim failure screen 2. A = the override loaded automatically and the mock claim passed; nothing more to do. Per the WI no pop-up appears, and you should NOT check the override in AS400 or run a test claim | E36: Three outcomes: back to Member Center, Override screen, Mock Claim failure | F36: Not listed | G36: No | H36: No | I36: P1 16, 17A / - / - | J36: None (CAS screen the reviewer lands on). | K36: Info only. If back to Member Center, do nothing and do not run a test claim.
A37: 25 | B37: Override | C37: Place the override / macro by hand | D37: Load the override by hand (Wegovy, when CAS shows the Override screen). 1. In CAS: pick the client-type profile (for example Agent H, Reason OD, Ignore PA P, Over Sp Rx N, Drug status F, Clinical/Admin C). Route of Administration Y, Expiration Message Y. GPI / NDC from the approval message or guidelines, daily dose + S, QVT if required. Click Create once. 2. In AS400: PA number = your initials + date + sequence 3. 717-A: check the partial macro flag (this row is empty in Process 2) | E37: Yes if CAS does not auto-load (partial macro via OFU 2.0 v2; full macro 1150 = approval term only) | F37: Yes - check partial macro flag (open in Process 2) | G37: No, except CA CoC approvals (RPh) | H37: No | I37: P1 17B / P2 12 / - | J37: Approval message; GPI / NDC; daily dose; QVT; client-type profile; PA number for AS400. | K37: Wegovy and 717-A share the override panel. Riskiest build.
... A44: 32 | B44: Side paths | C44: Problem tickets and feedback | D44: 1. Smart Routing errors go to the Smart Routing team. Wrong PASTA messages go on the PASTA Feedback Form | E44: Smart Routing errors, PASTA Feedback Form | F44: Not listed | G44: Not listed | H44: No | I44: P1 S3 / - / - | J44: None. | K44: Process, not case work.

Sheet Wegovy PAC131011 ->

Sheet Work Instruction Index (WIP)
A14: WI No | B14: Main Link (original) | C14: Description (original) | D14: Step (original draft) | E14: Title on thesource | F14: Last modified (thesource) | G14: Used by | H14: What it covers | I14: Where it fits in the Wegovy flow | J14: AS400? | K14: PA Caddie relevance
A15: 1 | B15: https://thesource.cvshealth.com/nuxeo/thesource/#!/view?docid=0ff3e9b0-fb4d-4360-9978-0b04d5dea665 | C15: ePA Process (Loop 2) - Commercial Specialty | E15: ePA Process (Loop 2) – Commercial Specialty | F15: 2026-08-12 | G15: Tech/Nurse/RPh | H15: Main ePA Loop 2 review flow: take the case, verify drug, claim, history, criteria, answers and documents, then close. | I15: Whole flow (steps 1-18) | J15: Yes (override look-up, void override on denial) | K15: Core
A16: 1.a | B16: https://thesource.cvshealth.com/nuxeo/thesource/#!/view?docid=c650ce09-e07a-4894-bb68-8acb99e539a7 | C16: Downtime Procedure for ePA Loop 2 - Commercial Specialty | E16: Downtime Procedure for ePA Loop 2 – Commercial Specialty | F16: 2026-08-19 | G16: Tech | H16: Same review when Smart Routing is down; adds how to open ePA queues and read the fallout reason. | I16: Step 1 (only when tool is down) | J16: Yes | K16: Conditional
A17: 1.b | B17: https://thesource.cvshealth.com/nuxeo/thesource/#!/view?docid=998b127b-ba26-4f54-959a-9a90311577a8 | C17: Creating an ePA starter via CoverMyMeds – Commercial Specialty | E17: Creating an ePA starter via CoverMyMeds – Commercial Specialty | F17: 2026-06-15 | G17: Tech | H17: Start an ePA through CoverMyMeds when a provider calls. | I17: Not in the standard ePA flow | J17: No | K17: Conditional
A18: 1.c | B18: https://thesource.cvshealth.com/nuxeo/thesource/#!/view?docid=f409aff0-e6da-4289-b885-3f90bfa06f7e | C18: Clinical Operations - Artificial Intelligence (AI) Contextualization 2.0 | E18: Clinical Operations - Artificial Intelligence (AI) Contextualization 2.0 | F18: 2026-09-30 | G18: Tech | H18: AI summary and question validation in Autonomize (ePA only, certain PACs). | I18: Steps 9-10 (if the case has an AI link) | J18: No | K18: Not typical for PAC131011
A19: 1.d | B19: https://thesource.cvshealth.com/nuxeo/thesource/#!/view?docid=2dd6f8ad-d1a1-4707-81b5-c64ee818fa6a | C19: Clinical Operations – PASTA/Smart Routing | D19: Run a Test Claim in CAS & Validate a PA is Needed | E19: Clinical Operations - PASTA/Smart Routing | F19: 2026-07-08 | G19: Tech | H19: How Get Next works, PASTA message meaning, error codes, feedback and support ticket. | I19: Steps 1-2, 18 | J19: No | K19: Core
A20: 1.e | B20: https://thesource.cvshealth.com/nuxeo/thesource/#!/view?docid=c55b5ef6-ca30-401a-bdb9-df8b47b1ca56 | C20: Attaching Claims to PAs in CAS- Commercial Specialty | D20: Attach a Rejected Claim | E20: Attaching Claims to PAs in CAS- Commercial Specialty | F20: 2026-06-05 | G20: Tech | H20: How to attach the right rejected claim and which rejection codes qualify. | I20: Step 4 | J20: No | K20: Core
A21: 1.f | B21: https://thesource.cvshealth.com/nuxeo/thesource/#!/view?docid=fb639e99-4bb0-4917-b19f-a5c14b370ea8 | C21: Opening a New PA in CAS - Commercial Specialty | D21: Run a Test Claim in CAS & Validate a PA is Needed | E21: Opening a New PA in CAS – Commercial Specialty | F21: 2026-10-07 | G21: Tech | H21: How to tell if a PA is needed, run a mock claim, open a new PA, and finish. | I21: Steps 5-6 (and new-PA path) | J21: Optional | K21: Core
A22: 1.g | B22: https://thesource.cvshealth.com/nuxeo/thesource/#!/view?docid=360069c5-15a5-4173-8fa1-efffd3c4c70e | C22: Viewing and Utilizing PA History in CAS – Commercial Specialty | D22: Verify PA History | E22: Viewing and Utilizing PA History in CAS – Commercial Specialty | F22: 2026-06-10 | G22: Tech | H22: What each PA History tab shows. | I22: Steps 2, 6, 10 | J22: No | K22: Core
A23: 1.h | B23: https://thesource.cvshealth.com/nuxeo/thesource/#!/view?docid=b434c5a9-9527-497d-be6f-d9f05eead6dc | C23: Communications Tool Resource and Quick Guide – Commercial Specialty | D23: If handled by dedicated team, IM the team the PA # and do not work the case | E23: Communications Tool Resource and Quick Guide – Commercial Specialty | F23: 2026-07-08 | G23: All | H23: Quick list of phone numbers, fax numbers, Teams tags and contact etiquette. | I23: Step 2 (dedicated team contact) | J23: No | K23: Reference
A24: 1.i | B24: https://thesource.cvshealth.com/nuxeo/thesource/#!/view?docid=a309f785-475f-450a-b9b5-7f46d4a03bcd | C24: RFI (Request for Information) - Commercial Specialty | D24: 1. If closing a duplicate ePA, put in your notes that the ePA is being aborted due to it being a duplicate case and reference the valid PA number 2. Criteria is incomplete or needs to be clarified 3. Documentation is not attached or incomplete | E24: RFI (Request for Information) - Commercial Specialty | F24: 2026-06-03 | G24: Tech/Nurse | H24: How to send a Request for Information to the provider and the templates. | I24: Side path S1 | J24: No | K24: Conditional
A25: 1.j | B25: https://thesource.cvshealth.com/nuxeo/thesource/#!/view?docid=345bc3d3-ede6-45e5-a3ef-52ff4f3d8062 | C25: Clinical Operations - Auto Note Tool | D25: If closing a duplicate ePA, put in your notes that the ePA is being aborted due to it being a duplicate case and reference the valid PA number. | E25: Clinical Operations - Auto Note Tool | F25: 2026-10-07 | G25: Tech/Nurse/RPh | H25: How to build the PA note with the Auto Note tool. | I25: Step 13 | J25: No | K25: Core
A26: 1.k | B26: https://thesource.cvshealth.com/nuxeo/thesource/#!/view?docid=c27b47b5-380d-489f-9113-00d8696980b3 | C26: Adding a PA Note or Member Note in CAS (Techs) - Commercial Specialty | D26: If closing a duplicate ePA, put in your notes that the ePA is being aborted due to it being a duplicate case and reference the valid PA number. | E26: Adding a PA Note or Member Note in CAS (Techs) - Commercial Specialty | F26: 2026-07-17 | G26: Tech | H26: What goes in a PA note, note templates, and member-note types. | I26: Step 13 | J26: No | K26: Core
A27: 1.l | B27: https://thesource.cvshealth.com/nuxeo/thesource/#!/view?docid=279c9fce-4f64-495f-8fa0-05f869d7f7b3 | C27: Rejection Codes & Determining if PA Review Needed - Commercial Specialty | D27: ePA Duplicate Approval PAG/PAC/Drug, Fails for other reasons (Non- PA required), Use available resources to troubleshoot why mock claim does not pay | E27: Rejection Codes & Determining if PA Review Needed - Commercial Specialty | F27: 2026-10-07 | G27: Tech | H27: How to read mock-claim reject codes and decide if Commercial Specialty reviews the PA. | I27: Step 5 | J27: Optional | K27: Core
A28: 1.m | B28: https://thesource.cvshealth.com/nuxeo/thesource/#!/view?docid=e3cbfb14-8856-40cf-a8ab-3aafd9b91f1b | C28: Internal Reporting for HIPAA Violations - Commercial Specialty | D28: Verify All Required Documentation is Provided and Accurate, Incorrect patient | E28: Internal Reporting for HIPAA Violations - Commercial Specialty | F28: 2026-06-05 | G28: All | H28: Reporting wrong-patient documents or other privacy problems. | I28: Step 10 (wrong patient attachment) | J28: No | K28: Conditional
A29: 1.n | B29: https://thesource.cvshealth.com/nuxeo/thesource/#!/view?docid=c27b47b5-380d-489f-9113-00d8696980b3 | C29: Adding a PA Note or Member Note in CAS (Techs) - Commercial Specialty | D29: Tech: Close Options tab to select the appropriate close option, Meets guidelines, Enter a PA Note. Depending on role | E29: Adding a PA Note or Member Note in CAS (Techs) - Commercial Specialty | F29: 2026-07-17 | G29: Tech | H29: Same thesource document as 1.k (duplicate row). | I29: Step 13 | J29: No | K29: Core
A30: 1.o | B30: https://thesource.cvshealth.com/nuxeo/thesource/#!/view?docid=5acb68cd-7534-4022-b1ef-369938da08e4 | C30: PA and Member Notes for Nurses - Commercial Specialty | D30: Nurse: Close Options tab to select the appropriate close option, Meets guidelines, Enter a PA Note. Depending on role | E30: PA and Member Notes for Nurses- Commercial Specialty | F30: 2026-04-10 | G30: Nurse | H30: Note-writing rules for nurses. | I30: Step 13 (nurse path) | J30: No | K30: Conditional
... A35: 1.t | B35: https://thesource.cvshealth.com/nuxeo/thesource/#!/view?docid=e68acd9f-bacd-4be0-966c-f35309ba0db6 | C35: RFI Lack of Information Autoclosure (RPh only) – Commercial Specialty | D35: RFI Soft Denials (RPh only), There are now close options which combine both RFI and denial setup | E35: RFI Lack of Information Autoclosure (RPh only) – Commercial Specialty | F35: 2026-05-06 | G35: RPh | H35: Combined RFI + soft denial close options for lack of information. | I35: Side path S1 (RPh) | J35: No | K35: Conditional
A36: 2 | B36: https://thesource.cvshealth.com/nuxeo/thesource/#!/view?docid=90a426f3-1140-4210-ad38-e14e31823c2b | C36: Commercial PA – Weight Loss Wegovy PA with Limit Criteria | E36: Commercial PA – Weight Loss Wegovy PA with Limit Criteria | F36: 2026-10-07 | G36: Tech/RPh | H36: Question-by-question checks for criteria PAC131011 Weight Loss Wegovy PA with Limit. | I36: Steps 7, 9-11 | J36: Yes (paid claims, quantity) | K36: Core
A37: 3 | B37: https://thesource.cvshealth.com/nuxeo/thesource/#!/view?docid=45e7ff5a-f1c8-43db-a67c-f057316e1ec0 | C37: Commercial PA - Weight Loss Management Job Aid | E37: Commercial PA - Weight Loss Management Job Aid | F37: 2026-10-07 | G37: Tech/RPh | H37: Rules for age, maintenance dose, weight loss, BMI, comorbidity, OSA and dosing on weight-loss criteria, with the calculations. | I37: Steps 9-11 | J37: Yes (paid claims, quantity) | K37: Core
A38: 4 | B38: https://thesource.cvshealth.com/nuxeo/thesource/#!/view?docid=b90c0882-e4fd-4ec5-9cba-1f0d7e71cc1d | C38: Commercial PA - Zepbound Non-Formulary Prior Authorization Process | E38: Commercial PA - Zepbound Non-Formulary Prior Authorization Process | F38: 2026-09-30 | G38: Tech/RPh | H38: Zepbound non-formulary process; says what to do when the provider switches to Wegovy. | I38: Side path S2 | J38: No | K38: Conditional

Sheet Consolidated Process View (WIP 
O11: Applies to which criteria
D13: # | E13: Phase | F13: Step | G13: What happens (plain language) | H13: Decision / branch | I13: System | J13: AS400? | K13: AS400 used for | L13: Role | M13: Source WI | N13: Workshop observation (Ops Reviewer and US 1-1) | O13: Wegovy, PAC131011 | P13: 717-A, PACXYZABC | Q13: IBRs, PACDEFGHI
C14: KC Example ->> | D14: 1 | E14: 1. Get the case | F14: 1 | G14: Get the PA. Click Get Next in Smart Routing; the PA opens in CAS with the PASTA message (fallout reason + actions to do). A tech can also pull a PA by hand from the queue | H14: Manual pull: no PASTA message, tech does all validation. Smart Routing down: use the Downtime WI | I14: Smart Routing; CAS | J14: No | L14: Tech | M14: 1, 1.d, 1.a
B15: Wegovy
B16: 717-A
B17: IBR
D21: Only include steps in the happy path (ePA & Loop2). Detail of all branches (unhappy path steps) are in Process 3 sheet | E21: Check No PA Required | F21: 1 | G21: Review the rejection or test claim messaging to ensure that the drug does not require a PA. | I21: CAS | M21: Non-PA Benefit Reject Types: https://thesource.cvshealth.com/nuxeo/thesource/#!/view?docid=aa12cac0-21e7-4b9b-bbec-281ab997d694
F22: 2 | G22: Check Red Message tab for additional information regarding Client and rejection(s). | I22: CAS - Red Message Tab
E23: Check no applicable criteria/form exists | F23: 3 | G23: Check CAS to ensure a criteria form is not available for the requested medication. | H23: If the criteria form is available, forward to the Seniors (014515) for further evaluation. | I23: CAS | M23: Submitting Request to Senior Team: https://thesource.cvshealth.com/nuxeo/thesource/#!/view?docid=f3d54724-6ec1-48a8-929d-c7342b4c250d
E24: Check IBR history/timing | F24: 4 | G24: Review the PA History and Notes and see if there is: • TWO IBRs on file within last 60 days • Only ONE IBR on file within last 60 days • NO IBR on file • New MD | H24: If Only ONE IBR within last 60 days, NO IBR on file, or New MD, go to step 5 | I24: CAS
E25: Check no exception path available | F25: 5 | G25: Check for possible Exceptions Review. Check the red Messages tab in CAS to ensure the member does not have an exception available for the rejection type. | H25: If no exception available, go to Step 6. | I25: CAS - Red Message Tab
E26: Check if IBR is allowed by the plan | F26: 6 | G26: Verify RMT if IBR is able to be sent. | H26: If IBR is allowed by the plan, Proceed to Step 7. | I26: RMT???
E27: Complete the IBR | F27: 7 | G27: Complete the IBR per the standard process. Refer to Commercial PA - How to Create a New PA (067801). | M27: https://thesource.cvshealth.com/nuxeo/thesource/#!/view?docid=e281d3f4-4b20-4c72-ae45-cf586fe10b74
E28: Complete the IBR | F28: 7-3 | G28: ePA Loop 2 | H28: Follow steps in the Smart Routing Tool. See Commercial PA - ePA Process (Loop 2) (105844). | I28: Smart Routing Tool
E29: Check Client Plan | F29: 8 | G29: Check Plan | H29: If Client is Commercial and NOT a California (CA) plan, Then: • Select the close option Initial Benefit Review. • Proceed to the next step. | I29: CAS - Close Options Tab???
E30: Choose denial reason | F30: 9 | G30: Select the appropriate Resolution Reason on the Denial Tab. | H30: Check the link for denial option logic details: https://thesource.cvshealth.com/nuxeo/thesource/#!/view?docid=7d8764dd-e788-47c5-9f4a-fcd65d4d2b93 | I30: CAS - Close Options Tab???
E31: Close the case | F31: 10 | G31: Enter a single space in the Member Denial note section. | I31: CAS - Close Options Tab???
E32: Close the case | F32: 11 | G32: Select your title from the Concluded by drop down and click OK. | I32: CAS - Close Options Tab???
E33: Close the case | F33: 12 | G33: Document your notes in CAS and click Finish. | I33: CAS - Close Options Tab???

Sheet WF 1
G4: Segment | H4: Your table | I4: Mine (case_smry, original review) | J4: Avg tasks per case (Task only) | K4: Avg incl. touches | O4: PAC | P4: Segment | Q4: Cases | R4: Avg tasks per case (Task only) | S4: Avg incl. touches
G5: All ePAs | H5: 913153 | I5: 912534 | J5: 1.06 | K5: 2.38 | O5: PAC20883 | P5: All (all human) | Q5: 389099 | R5: 1.84 | S5: 1.88
G6: Auto approved | H6: 239853 | I6: 239853 | J6: 0.1 | K6: 4.3 | P6: Scored approval | Q6: 286162 | R6: 2.06 | S6: 2.1
G7: Human reviewed | H7: 673300 | I7: 672681 | J7: 1.41 | K7: 1.7 | P7: Scored denial | Q7: 9299 | R7: 1.4 | S7: 1.48
G8: Scored approval | H8: 358815 | I8: 357742 | J8: 1.76 | K8: 2.04 | P8: Unscored | Q8: 93638 | R8: 1.21 | S8: 1.27
G9: Scored denial | H9: 181455 | I9: 180775 | J9: 1.23 | K9: 1.27 | O9: PAC33295 | P9: All (all human) | Q9: 89673 | R9: 1.82 | S9: 1.99
G10: Unscored | H10: 133030 | I10: 134164 | J10: 0.72 | K10: 1.35 | P10: Scored approval | Q10: 50082 | R10: 2.47 | S10: 2.54
P11: Scored denial | Q11: 22494 | R11: 1.27 | S11: 1.29
P12: Unscored | Q12: 17097 | R12: 0.63 | S12: 1.32
D14: Oct 2025 - Sept 2026, Wegovy PAC 131011 | E14: All PA Cases | F14: All Orgnl Review Approvals | G14: %Approval Rate | H14: Orgnl Review Ops Cost | I14: Orgnl Review HT | J14: Appeals Ops cost | K14: Appeals Review HT | L14: AHT (Sec)
D15: All PA Cases | E15: 1026562 | F15: 701743 | G15: =IFERROR(F15/E15, 0) -> 0.6835856 | H15: 7290979 | I15: 285759339 | J15: 1746932 | K15: 74511471 | L15: =IFERROR((I15+K15)/E15, 0) -> 350.94891
D16: IBRs | E16: 0 | F16: 0 | G16: =IFERROR(F16/E16, 0) -> 0 | H16: 0 | I16: 0 | J16: 0 | K16: 0 | L16: =IFERROR((I16+K16)/E16, 0) -> 0
D17: Data Entry | E17: 0 | F17: 0 | G17: =IFERROR(F17/E17, 0) -> 0 | H17: 0 | I17: 0 | J17: 0 | K17: 0 | L17: =IFERROR((I17+K17)/E17, 0) -> 0
D18: Medicaid | E18: 0 | F18: 0 | G18: =IFERROR(F18/E18, 0) -> 0 | H18: 0 | I18: 0 | J18: 0 | K18: 0 | L18: =IFERROR((I18+K18)/E18, 0) -> 0
D19: SPC | E19: 0 | F19: 0 | G19: =IFERROR(F19/E19, 0) -> 0 | H19: 0 | I19: 0 | J19: 0 | K19: 0 | L19: =IFERROR((I19+K19)/E19, 0) -> 0
D20: Commercial Only | E20: 1026562 | F20: 701743 | G20: =IFERROR(F20/E20, 0) -> 0.6835856 | H20: 7290979 | I20: 285759339 | J20: 1746932 | K20: 74511471 | L20: =IFERROR((I20+K20)/E20, 0) -> 350.94891
D21: Appeals | E21: 33615 | F21: 0 | G21: =IFERROR(F21/E21, 0) -> 0 | H21: 457420 | I21: 15586363 | J21: 1746932 | K21: 74511471 | L21: =IFERROR((I21+K21)/E21, 0) -> 2680.2866
D22: Original Review | E22: =E20-E21 -> 992947 | F22: =F20-F21 -> 701743 | G22: =IFERROR(F22/E22, 0) -> 0.70672755 | H22: =H20-H21 -> 6833559 | I22: =I20-I21 -> 270172976 | J22: =J20-J21 -> 0 | K22: =K20-K21 -> 0 | L22: =IFERROR((I22+K22)/E22, 0) -> 272.09204
D23: Non ePAs | E23: 79794 | F23: 51689 | G23: =IFERROR(F23/E23, 0) -> 0.64778053 | H23: 1384571 | I23: 67601852 | L23: =IFERROR((I23+K23)/E23, 0) -> 847.2047
D24: Faxes | E24: 55006 | F24: 36273 | G24: =IFERROR(F24/E24, 0) -> 0.65943715 | H24: 1045585.8 | I24: 50915501 | J24: 0 | K24: 0 | L24: =IFERROR((I24+K24)/E24, 0) -> 925.6354
D25: Non Full Macro (Partial, No Macro) | E25: 19248 | F25: 556 | G25: =IFERROR(F25/E25, 0) -> 0.028886118 | H25: 415255.27 | I25: 18852635 | J25: 0 | K25: 0 | L25: =IFERROR((I25+K25)/E25, 0) -> 979.45942
D26: Phone/Calls | E26: 12493 | F26: 8053 | G26: =IFERROR(F26/E26, 0) -> 0.64460098 | H26: 173341.18 | I26: 8747560 | J26: 0 | K26: 0 | L26: =IFERROR((I26+K26)/E26, 0) -> 700.19691
D27: Non Full Macro (Partial, No Macro) | E27: 4506 | F27: 80 | G27: =IFERROR(F27/E27, 0) -> 0.017754106 | H27: 52272.907 | I27: 2407778 | J27: 0 | K27: 0 | L27: =IFERROR((I27+K27)/E27, 0) -> 534.34931
D28: Others | E28: 12295 | F28: 7363 | G28: =IFERROR(F28/E28, 0) -> 0.59886133 | H28: 165644.22 | I28: 7938791 | J28: 0 | K28: 0 | L28: =IFERROR((I28+K28)/E28, 0) -> 645.69264
D29: Non Full Macro (Partial, No Macro) | E29: 5003 | F29: 82 | G29: =IFERROR(F29/E29, 0) -> 0.016390166 | H29: 55241.736 | I29: 2431552 | J29: 0 | K29: 0 | L29: =IFERROR((I29+K29)/E29, 0) -> 486.01879
C30: =E30/E22 -> 0.91963922 | D30: ePAs | E30: 913153 | F30: 650054 | G30: =IFERROR(F30/E30, 0) -> 0.71187851 | H30: 5448988.2 | I30: 202571124 | J30: 0 | K30: 0 | L30: =IFERROR((I30+K30)/E30, 0) -> 221.837
C31: =E31/E15 -> 0.23364687 | D31: ePAs Auto Approved | E31: 239853 | F31: 239853 | G31: =IFERROR(F31/E31, 0) -> 1 | H31: 48701 | I31: 2600030 | L31: =IFERROR((I31+K31)/E31, 0) -> 10.840098
C32: =E32/E30 -> 0.73733536 | D32: ePAs Human Reviewed | E32: =E30-E31 -> 673300 | F32: =F30-F31 -> 410201 | G32: =IFERROR(F32/E32, 0) -> 0.60923957 | H32: =H30-H31 -> 5400287.2 | I32: =I30-I31 -> 199971094 | L32: =IFERROR((I32+K32)/E32, 0) -> 297.00148
C33: =E33/E32 -> 0.53291995 | D33: ePA Scored Approval | E33: 358815 | F33: 306354 | G33: =IFERROR(F33/E33, 0) -> 0.85379374 | H33: 3151440 | I33: 137156503 | J33: 0 | K33: 0 | L33: =IFERROR((I33+K33)/E33, 0) -> 382.24852
C34: =E34/E33 -> 0.19624876 | D34: Non Full Macro (Partial, No Macro) | E34: 70417 | F34: 18563 | G34: =IFERROR(F34/E34, 0) -> 0.26361532 | H34: 1009029 | I34: 38011553 | J34: 0 | K34: 0 | L34: =IFERROR((I34+K34)/E34, 0) -> 539.80648
D35: ePA Scored Denial | E35: 181455 | F35: 84875 | G35: =IFERROR(F35/E35, 0) -> 0.46774682 | H35: 1744584 | I35: 45079671 | L35: =IFERROR((I35+K35)/E35, 0) -> 248.43444 | N35: =H33/H32 -> 0.58356896
D36: Non Full Macro (Partial, No Macro) | E36: 96184 | F36: 433 | G36: =IFERROR(F36/E36, 0) -> 0.0045017882 | H36: 768902 | I36: 20152695 | L36: =IFERROR((I36+K36)/E36, 0) -> 209.52232
D37: ePA Unscored | E37: =E32-(E33+E35) -> 133030 | F37: =F32-(F33+F35) -> 18972 | G37: =IFERROR(F37/E37, 0) -> 0.14261445 | H37: =H32-(H33+H35) -> 504263.21 | I37: =I32-(I33+I35) -> 17734920 | L37: =IFERROR((I37+K37)/E37, 0) -> 133.31519
D38: Non Full Macro (Partial, No Macro) | E38: 114090 | F38: 110 | G38: =IFERROR(F38/E38, 0) -> 0.00096415111 | H38: 251487.93 | I38: 9157580 | J38: 0 | K38: 0 | L38: =IFERROR((I38+K38)/E38, 0) -> 80.266281
D41: Original Review PAs, Human Reviewed | E41: =E23+E32 -> 753094 | F41: =F23+F32 -> 461890 | G41: =F41/E41 -> 0.61332317 | H41: =H23+H32 -> 6784858.2 | I41: =I23+I32 -> 267572946 | J41: =J23+J32 -> 0 | K41: =K23+K32 -> 0 | L41: =IFERROR((I41+K41)/E41/60, 0) -> 5.9216367
D42: Fell out of GLP1 Model (WIP), think about why model could not do
C43: =E43/E41 -> 0.41090222 | D43: PAs requiring Override Support | E43: =E25+E27+E29+E34+E36+E38 -> 309448 | F43: =F25+F27+F29+F34+F36+F38 -> 19824 | G43: =F43/E43 -> 0.06406246 | H43: =H25+H27+H29+H34+H36+H38 -> 2552188.8 | I43: =I25+I27+I29+I34+I36+I38 -> 91013793 | J43: =J25+J27+J29+J34+J36+J38 -> 0 | K43: =K25+K27+K29+K34+K36+K38 -> 0 | L43: =IFERROR((I43+K43)/E43/60, 0) -> 4.9019433
D45: Original Review ePAs, Human Reviewed | E45: =E32 -> 673300 | F45: =F32 -> 410201 | G45: =F45/E45 -> 0.60923957 | H45: =H32 -> 5400287.2 | I45: =I32 -> 199971094 | J45: =J32 -> 0 | K45: =K32 -> 0 | L45: =IFERROR((I45+K45)/E45/60, 0) -> 4.9500246
D46: Fell out of GLP1 Model (WIP)
C47: =E47/E45 -> 0.41688846 | D47: PAs requiring Override Support | E47: =E34+E36+E38 -> 280691 | F47: =F34+F36+F38 -> 19106 | G47: =F47/E47 -> 0.068067733 | H47: =H34+H36+H38 -> 2029418.9 | I47: =I34+I36+I38 -> 67321828 | J47: =J34+J36+J38 -> 0 | K47: =K34+K36+K38 -> 0 | L47: =IFERROR((I47+K47)/E47/60, 0) -> 3.9973867
...

Sheet Process 1
N10: Column M = KC's X marks (unchanged). Column N = Claude's call + short reason, added in v2.
A11: # | B11: Phase | C11: Step | D11: What happens (KC's plain language) | E11: Decision / branch | F11: System | G11: AS400 / RxClaim? | H11: AS400 used for | I11: Role | J11: Source WI | K11: Workshop observation (Ops Reviewer and KC 1-1) | L11: KC Started Building the logic | M11: Required for PA Caddie? | N11: Claude: required for PA Caddie? (Yes / Partly / Later / No) + why
A12: 1 | B12: 1 Get the case | C12: 1 | D12: Get the PA. Click Get Next in Smart Routing; the PA opens in CAS with the PASTA message (fallout reason + actions to do). A tech can also pull a PA by hand from the queue | E12: Manual pull: no PASTA message, tech does all validation. Smart Routing down: use the Downtime WI | F12: Smart Routing; CAS | G12: No | I12: Tech | J12: 1, 1.d, 1.a | K12: Reviewer pulled by hand, so she had no Smart Routing message and did every check herself | M12: X | N12: Yes - Caddie has to load the PA. In V1 the case comes in from the ePA feed (fell-out ePAs), not from Smart Routing 'Get Next'.
A13: 2 | B13: 1 Get the case | C13: 2 | D13: Read the PASTA message and the Messages, Guidelines, Work Instructions and red Message tabs. Follow the actions listed | E13: Dedicated-team client (e.g., Wellmark, FLBL, HealthFirst): IM the team with the PA # and stop. | F13: CAS; MS Teams | G13: No | I13: Tech | J13: 1, 1.d, 1.h | M13: X | N13: Yes - show the fallout reason and client flags up front (dedicated-team client = stop and IM the team). Replaces reading 4 tabs.
A14: 3 | B14: 2 Is a PA really needed? | C14: 3 | D14: Verify the drug: on PA Info, re-select the drug from the drop-down (even if prepopulated) so the right macros load. Check strength, brand vs generic, form against the claim. | E14: GPI can be matched from the claim in AS400. Only option 'Other, please Specify': move on | F14: CAS | G14: Optional | H14: GPI look-up from the claim | I14: Tech | J14: 1 | K14: Reviewer verified drug and strength; some criteria are wildcarded at GPI level. | L14: WIP | M14: X | N14: Yes - first Caddie check (Drug Verification in the UI). Our CAS drug-name resolver gives the suggestion; reviewer confirms.
A15: 4 | B15: 2 Is a PA really needed? | C15: 4 | D15: Make sure the correct rejected claim is attached (Claims tab). If you attach one, click Cancel on the next pop-up. | E15: Attached and right: leave it. No rejected claim: do not tick 'Rejected Claim Not Available' (ePA) | F15: CAS | G15: No | I15: Tech | J15: 1, 1.e | L15: WIP | M15: X | N15: Yes, show only - Caddie shows the rejected claim from intake. Attaching it stays in CAS.
A16: 5 | B16: 2 Is a PA really needed? | C16: 5 | D16: Run a mock claim (today, +30, +60 days; never +90) and read the rejection. | E16: PA required (75/70 with a Commercial Specialty number): continue. Pays: check overrides (step 6). Refill too soon (79): rerun at the Next Available Fill Date to see the true reject. Other codes: see the rejection WI | F16: CAS (Mock Claim) | G16: Optional | H16: extra mock in AS400 | I16: Tech | J16: 1, 1.f, 1.l | K16: Reviewer ran mocks to learn what RxClaim is doing. She used the 30-day option to get past refill-too-soon; the real reject was 'PA Required'. | L16: WIP | M16: X | N16: Yes - Mock Claim Review. Shows the reject (70/75/76) and the Commercial PA phone. PRAAS is QA2-only, so V1 uses the intake reject plus CAS mock results.
A17: 6 | B17: 2 Is a PA really needed? | C17: 6 | D17: Check PA History for an active approval or an override the system loaded | E17: Auto-approved by System Services: complete normally (duplicate override, void neither). VTPA / plan-sponsor override in AS400: rerun mock after it expires, complete, do not abort. Duplicate approval / denial / pending: duplicate rules, close with ePA Abort | F17: CAS (PA History); RxClaim/AS400 | G17: Yes (If CAS Prod data is accurate) | H17: override look-up | I17: Tech | J17: 1, 1.g, 1.l | K17: Reviewer reviews PA history first on any PA: prior approval valid or expiring? legitimate work today? | L17: WIP | N17: Yes - differ from blank. The UI already has a PA History step and an active approval / duplicate changes the whole outcome. Depends on CAS PROD data being right (your AS400 note).
A18: 7 | B18: 3 Right criteria | C18: 7 | D18: Confirm the criteria is PAC131011 Weight Loss Wegovy PA with Limit: 1. Change PA Type/Drug Class -> click the rejected claim to fill reject code / phone / GPI, Search, pick the PAC | E18: Right form: Cancel then Save. Wrong form: change it in the same case and re-enter the drug. Several forms: call Vetline | F18: CAS | G18: Optional | I18: Tech | J18: 1, 1.f, 2 | K18: Reviewer uses this screen to validate rejection mapping, drug and strength, then backs out (continuing would act like a new PA) | L18: WIP | M18: X | N18: Yes - Criteria Review. Check the QSet and drug / reject phone match PAC131011. Changing the form stays in CAS.
A19: 8 | B19: 3 Right criteria | C19: 8 | D19: Check ICD-10 and that Drug Name matches what we are approving (Requested Drug is the original ask) | E19: If the provider agrees to switch drugs in the QSet, update Drug Name and rerun the mock claim | F19: CAS | G19: No | I19: Tech | J19: 1, 4 | L19: WIP | M19: X | N19: Yes - ICD-10 is on the intake row; show it next to the drug name.
A20: 9 | B20: 4 Check the provider's answers (PAC131011) | C20: 9 | D20: Work the Wegovy questions. Accept the attestation questions as is; 1. verify age in CAS 2. check maintenance dose and continuation in AS400 paid claims 3. check quantity and day supply in AS400 4. verify the drug / formulation | E20: Quantity above plan allowance, or any 'No' on a program / diet / maintenance-dose attestation: forward to RPh | F20: CAS; RxClaim/AS400 | G20: Yes (or check the mock claim results) | H20: paid claims, quantity | I20: Tech | J20: 2, 3 | L20: Need to Start | M20: X | N20: Yes - core of the pilot. Age, maintenance dose / continuation, quantity and day supply from claim data; any 'No' on an attestation = forward to RPh.
A21: 10 | B21: 4 Check the provider's answers (PAC131011) | C21: 10 | D21: Open the attachments and read the chart notes for every 'ACTION REQUIRED' question: baseline and current weight with dates, baseline BMI, comorbid condition, CVD / GDMT or MASH evidence when that pathway applies Also look for anything that contradicts the answer, and confirm the documents are for the right patient | E21: Wrong patient: email the split-fax template to CRUSrTech@CVSHealth.com Documentation missing: RFI (or forward to RPh as the WI says | F21: CAS (Attachments) | G21: No | I21: Tech/Nurse | J21: 1, 2, 3, 1.m | K21: Most of Reviewer's time: scrolling chart notes for weights, dates and BMI; provider answers alone were not accepted. | L21: Need to Start | M21: X | N21: Partly - Caddie lists what to look for (weights + dates, BMI, comorbidity, CVD / MASH evidence). Reading the chart notes stays with the reviewer in V1.
A22: 11 | B22: 4 Check the provider's answers (PAC131011) | C22: 11 | D22: Calculate. Weight loss % = (weight before - weight after) / weight before x 100 Same for BMI. BMI = weight(lb) x 703 / height(in)^2 Do not round. Dates need at least month / year | E22: At least 5% loss (or BMI reduction / maintained loss for continuation): meets. Under 5%: complete denial | F22: Calculator workbook | G22: No | I22: Tech | J22: 2, 3 | K22: Reviewer used a calculator workbook (about 5% in her example) and recorded the numbers in the note | L22: Need to Start | M22: X | N22: Yes - easy win. Calculator replaces the workbook; reviewer types the weights and dates.
A23: 12 | B23: 4 Check the provider's answers (PAC131011) | C23: 12 | D23: Decide the outcome | E23: Meets: approve. Does not meet with complete clinical: Tech / Nurse pend to clinician, RPh denies Missing info: RFI. Anything the WI says to forward: RPh Red Messages tab needing a medical director: pend to clinician | F23: CAS | G23: No | I23: Tech/Nurse/RPh | J23: 1, 1.i, 1.q, 1.t | M23: X | N23: Yes - Case Decision step. Caddie recommends, reviewer decides (approve / pend / RFI / deny).
A24: 13 | B24: 5 Document and close | C24: 13 | D24: Write the PA note with Auto Note (finish drug name and criteria edits first): 1. outcome 2. ENTIRE approval message 3. what evidence was needed / where found / what found, dates and calculation | E24: Running Auto Note again erases the earlier Auto Note text. | F24: CAS (Auto Note) | G24: No | I24: Tech | J24: 1, 1.j, 1.k | K24: Reviewer wrote detailed notes for audit: weights, dates, % calculated, source of evidence | M24: X | N24: Yes - Auto Note. Same engine for all 3 PACs, different templates. Best first build.
A25: 14 | B25: 5 Document and close | C25: 14 | D25: Check the Completed Date timestamp auto-filled (copy RRD into CD if not, except for RFI) | F25: CAS | G25: No | I25: Tech | J25: 1 | N25: No - agree. CAS fills it. Nothing for Caddie.
A26: 15 | B26: 5 Document and close | C26: 15 | D26: Close Options: 1. 'Approved - ePA' (or the pend / RFI / denial option from step 12) 2. Copy approval duration and override instructions with the QSet Copy Dialog 3. Choose Resolution Reason, set approval dates from the duration 4. check Start / End 5. choose Concluded By, OK | E26: On a denial: first check System Services did not load an override; void it in AS400 | F26: CAS; RxClaim/AS400 (denial path) | G26: Yes | H26: denial path only | I26: Tech | J26: 1 | K26: Reviewer: EPA Approve, 'Concluded By' required (Tech, Pharmacist, Rep, LPN...), checked dates, saved | N26: Partly - differ from blank. Caddie suggests the close option and approval duration text; reviewer clicks it in CAS (no CAS write-back in V1).
A27: 16 | B27: 6 Override and finish | C27: 16 | D27: After OK, CAS goes one of three ways. A: back to Member Center B: Override screen C: Mock Claim failure screen | F27: CAS | G27: Depends | H27: See A / B / C | I27: Tech | J27: 1, 1.r, 1.s | K27: Reviewer saw no override screen and inferred the override was written automatically - FULL MACRO | N27: No - agree. CAS behavior. Caddie can just say what to expect.
